Workbook

Sheet approx true double perovskite
A1: Material ID | B1: Formula | C1: B-site metals | D1: Formation Energy (eV/atom) | E1: Energy Above Hull (eV) | F1: Band Gap (eV) | G1: Total Magnetization (Î¼B) | H1: Space Group | I1: Keep? | J1: element1 | K1: metallic radius1 | L1: element2 | M1: metallic radius 2 | N1: element3 | O1: metallic radius 3 | P1: element4 | Q1: metallic radius4 | R1: Magnetic State (inferred) | U1: Magnetic Transition (FM–PM / AFM–PM)
A2: mp-18967 | B2: Ba2CoMoO6 | C2: Co, Mo | D2: -2.4632855 | E2: 0 | F2: 0 | G2: 0.0109821 | H2: Fm-3m | I2: =TRUE() -> TRUE | J2: =IF(AND(CODE(MID(B2,2,1))>=97,CODE(MID(B2,2,1))<=122),LEFT(B2,2),LEFT(B2,1)) -> Ba | K2: =IF(J2="","",_xlfn.XLOOKUP(TRIM(J2),Metallic_Radius_Table!A:A,Metallic_Radius_Table!B:B)) -> 2.17 | L2: =IF(ISNUMBER(SEARCH("La",B2)),"La", IF(ISNUMBER(SEARCH("Nd",B2)),"Nd", IF(ISNUMBER(SEARCH("Eu",B2)),"Eu", IF(ISNUMBER(SEARCH("Gd",B2)),"Gd","")))) | M2: =IF(L2="","",_xlfn.XLOOKUP(TRIM(L2),Metallic_Radius_Table!A:A,Metallic_Radius_Table!B:B)) | N2: =TRIM(LEFT(C2,FIND(",",C2)-1)) -> Co | O2: =IF(N2="","",_xlfn.XLOOKUP(TRIM(N2),Metallic_Radius_Table!A:A,Metallic_Radius_Table!B:B)) -> 1.25 | P2: =TRIM(MID(C2,FIND(",",C2)+1,5)) -> Mo | Q2: =IF(P2="","",_xlfn.XLOOKUP(TRIM(P2),Metallic_Radius_Table!A:A,Metallic_Radius_Table!B:B)) -> 1.39 | R2: =IF(G2>=1, "Ferromagnetic / Ferrimagnetic", IF(G2>=0.05, "Paramagnetic / Weakly magnetic", "Antiferromagnetic / Diamagnetic")) -> Antiferromagnetic / Diamagnetic | U2: =IF(G2>=1, "FM → PM (Curie-type)", IF(G2<0.05, "AFM → PM (Néel-type)", "No long-range magnetic transition")) -> AFM → PM (Néel-type)
A3: mp-561894 | B3: Ba2CoMoO6 | C3: Co, Mo | D3: -2.4540698 | E3: 0.009215751 | F3: 1.274 | G3: 2.1e-06 | H3: I4/mmm | I3: =TRUE() -> TRUE | J3: =IF(AND(CODE(MID(B3,2,1))>=97,CODE(MID(B3,2,1))<=122),LEFT(B3,2),LEFT(B3,1)) -> Ba | K3: =IF(J3="","",_xlfn.XLOOKUP(TRIM(J3),Metallic_Radius_Table!A:A,Metallic_Radius_Table!B:B)) -> 2.17 | L3: =IF(ISNUMBER(SEARCH("La",B3)),"La", IF(ISNUMBER(SEARCH("Nd",B3)),"Nd", IF(ISNUMBER(SEARCH("Eu",B3)),"Eu", IF(ISNUMBER(SEARCH("Gd",B3)),"Gd","")))) | M3: =IF(L3="","",_xlfn.XLOOKUP(TRIM(L3),Metallic_Radius_Table!A:A,Metallic_Radius_Table!B:B)) | N3: =TRIM(LEFT(C3,FIND(",",C3)-1)) -> Co | O3: =IF(N3="","",_xlfn.XLOOKUP(TRIM(N3),Metallic_Radius_Table!A:A,Metallic_Radius_Table!B:B)) -> 1.25 | P3: =TRIM(MID(C3,FIND(",",C3)+1,5)) -> Mo | Q3: =IF(P3="","",_xlfn.XLOOKUP(TRIM(P3),Metallic_Radius_Table!A:A,Metallic_Radius_Table!B:B)) -> 1.39 | R3: =IF(G3>=1, "Ferromagnetic / Ferrimagnetic", IF(G3>=0.05, "Paramagnetic / Weakly magnetic", "Antiferromagnetic / Diamagnetic")) -> Antiferromagnetic / Diamagnetic | U3: =IF(G3>=1, "FM → PM (Curie-type)", IF(G3<0.05, "AFM → PM (Néel-type)", "No long-range magnetic transition")) -> AFM → PM (Néel-type)
A4: mp-545792 | B4: Ba2CoReO6 | C4: Re, Co | D4: -2.4478528 | E4: 0.048703632 | F4: 0.1982 | G4: 1.92e-05 | H4: R-3m | I4: =TRUE() -> TRUE | J4: =IF(AND(CODE(MID(B4,2,1))>=97,CODE(MID(B4,2,1))<=122),LEFT(B4,2),LEFT(B4,1)) -> Ba | K4: =IF(J4="","",_xlfn.XLOOKUP(TRIM(J4),Metallic_Radius_Table!A:A,Metallic_Radius_Table!B:B)) -> 2.17 | L4: =IF(ISNUMBER(SEARCH("La",B4)),"La", IF(ISNUMBER(SEARCH("Nd",B4)),"Nd", IF(ISNUMBER(SEARCH("Eu",B4)),"Eu", IF(ISNUMBER(SEARCH("Gd",B4)),"Gd","")))) | M4: =IF(L4="","",_xlfn.XLOOKUP(TRIM(L4),Metallic_Radius_Table!A:A,Metallic_Radius_Table!B:B)) | N4: =TRIM(LEFT(C4,FIND(",",C4)-1)) -> Re | O4: =IF(N4="","",_xlfn.XLOOKUP(TRIM(N4),Metallic_Radius_Table!A:A,Metallic_Radius_Table!B:B)) -> 1.37 | P4: =TRIM(MID(C4,FIND(",",C4)+1,5)) -> Co | Q4: =IF(P4="","",_xlfn.XLOOKUP(TRIM(P4),Metallic_Radius_Table!A:A,Metallic_Radius_Table!B:B)) -> 1.25 | R4: =IF(G4>=1, "Ferromagnetic / Ferrimagnetic", IF(G4>=0.05, "Paramagnetic / Weakly magnetic", "Antiferromagnetic / Diamagnetic")) -> Antiferromagnetic / Diamagnetic | U4: =IF(G4>=1, "FM → PM (Curie-type)", IF(G4<0.05, "AFM → PM (Néel-type)", "No long-range magnetic transition")) -> AFM → PM (Néel-type)
A5: mp-1228653 | B5: Ba2CoRuO6 | C5: Co, Ru | D5: -2.099805 | E5: 0.01920151 | F5: 0 | G5: 15.634939 | H5: P3m1 | I5: =TRUE() -> TRUE | J5: =IF(AND(CODE(MID(B5,2,1))>=97,CODE(MID(B5,2,1))<=122),LEFT(B5,2),LEFT(B5,1)) -> Ba | K5: =IF(J5="","",_xlfn.XLOOKUP(TRIM(J5),Metallic_Radius_Table!A:A,Metallic_Radius_Table!B:B)) -> 2.17 | L5: =IF(ISNUMBER(SEARCH("La",B5)),"La", IF(ISNUMBER(SEARCH("Nd",B5)),"Nd", IF(ISNUMBER(SEARCH("Eu",B5)),"Eu", IF(ISNUMBER(SEARCH("Gd",B5)),"Gd","")))) | M5: =IF(L5="","",_xlfn.XLOOKUP(TRIM(L5),Metallic_Radius_Table!A:A,Metallic_Radius_Table!B:B)) | N5: =TRIM(LEFT(C5,FIND(",",C5)-1)) -> Co | O5: =IF(N5="","",_xlfn.XLOOKUP(TRIM(N5),Metallic_Radius_Table!A:A,Metallic_Radius_Table!B:B)) -> 1.25 | P5: =TRIM(MID(C5,FIND(",",C5)+1,5)) -> Ru | Q5: =IF(P5="","",_xlfn.XLOOKUP(TRIM(P5),Metallic_Radius_Table!A:A,Metallic_Radius_Table!B:B)) -> 1.34 | R5: =IF(G5>=1, "Ferromagnetic / Ferrimagnetic", IF(G5>=0.05, "Paramagnetic / Weakly magnetic", "Antiferromagnetic / Diamagnetic")) -> Ferromagnetic / Ferrimagnetic | U5: =IF(G5>=1, "FM → PM (Curie-type)", IF(G5<0.05, "AFM → PM (Néel-type)", "No long-range magnetic transition")) -> FM → PM (Curie-type)
A6: mp-1274542 | B6: Ba2CoWO6 | C6: Co, W | D6: -2.5653992 | E6: 0.010751376 | F6: 1.8427 | G6: 3.0001636 | H6: I4/mmm | I6: =TRUE() -> TRUE | J6: =IF(AND(CODE(MID(B6,2,1))>=97,CODE(MID(B6,2,1))<=122),LEFT(B6,2),LEFT(B6,1)) -> Ba | K6: =IF(J6="","",_xlfn.XLOOKUP(TRIM(J6),Metallic_Radius_Table!A:A,Metallic_Radius_Table!B:B)) -> 2.17 | L6: =IF(ISNUMBER(SEARCH("La",B6)),"La", IF(ISNUMBER(SEARCH("Nd",B6)),"Nd", IF(ISNUMBER(SEARCH("Eu",B6)),"Eu", IF(ISNUMBER(SEARCH("Gd",B6)),"Gd","")))) | M6: =IF(L6="","",_xlfn.XLOOKUP(TRIM(L6),Metallic_Radius_Table!A:A,Metallic_Radius_Table!B:B)) | N6: =TRIM(LEFT(C6,FIND(",",C6)-1)) -> Co | O6: =IF(N6="","",_xlfn.XLOOKUP(TRIM(N6),Metallic_Radius_Table!A:A,Metallic_Radius_Table!B:B)) -> 1.25 | P6: =TRIM(MID(C6,FIND(",",C6)+1,5)) -> W | Q6: =IF(P6="","",_xlfn.XLOOKUP(TRIM(P6),Metallic_Radius_Table!A:A,Metallic_Radius_Table!B:B)) -> 1.41 | R6: =IF(G6>=1, "Ferromagnetic / Ferrimagnetic", IF(G6>=0.05, "Paramagnetic / Weakly magnetic", "Antiferromagnetic / Diamagnetic")) -> Ferromagnetic / Ferrimagnetic | U6: =IF(G6>=1, "FM → PM (Curie-type)", IF(G6<0.05, "AFM → PM (Néel-type)", "No long-range magnetic transition")) -> FM → PM (Curie-type)
A7: mp-22112 | B7: Ba2CoWO6 | C7: Co, W | D7: -2.5761506 | E7: 0 | F7: 0 | G7: 6.000052 | H7: R-3m | I7: =TRUE() -> TRUE | J7: =IF(AND(CODE(MID(B7,2,1))>=97,CODE(MID(B7,2,1))<=122),LEFT(B7,2),LEFT(B7,1)) -> Ba | K7: =IF(J7="","",_xlfn.XLOOKUP(TRIM(J7),Metallic_Radius_Table!A:A,Metallic_Radius_Table!B:B)) -> 2.17 | L7: =IF(ISNUMBER(SEARCH("La",B7)),"La", IF(ISNUMBER(SEARCH("Nd",B7)),"Nd", IF(ISNUMBER(SEARCH("Eu",B7)),"Eu", IF(ISNUMBER(SEARCH("Gd",B7)),"Gd","")))) | M7: =IF(L7="","",_xlfn.XLOOKUP(TRIM(L7),Metallic_Radius_Table!A:A,Metallic_Radius_Table!B:B)) | N7: =TRIM(LEFT(C7,FIND(",",C7)-1)) -> Co | O7: =IF(N7="","",_xlfn.XLOOKUP(TRIM(N7),Metallic_Radius_Table!A:A,Metallic_Radius_Table!B:B)) -> 1.25 | P7: =TRIM(MID(C7,FIND(",",C7)+1,5)) -> W | Q7: =IF(P7="","",_xlfn.XLOOKUP(TRIM(P7),Metallic_Radius_Table!A:A,Metallic_Radius_Table!B:B)) -> 1.41 | R7: =IF(G7>=1, "Ferromagnetic / Ferrimagnetic", IF(G7>=0.05, "Paramagnetic / Weakly magnetic", "Antiferromagnetic / Diamagnetic")) -> Ferromagnetic / Ferrimagnetic | U7: =IF(G7>=1, "FM → PM (Curie-type)", IF(G7<0.05, "AFM → PM (Néel-type)", "No long-range magnetic transition")) -> FM → PM (Curie-type)
A8: mp-1079901 | B8: Ba2CrMoO6 | C8: Cr, Mo | D8: -2.6602071 | E8: 0 | F8: 0 | G8: 3e-07 | H8: I4/mmm | I8: =TRUE() -> TRUE | J8: =IF(AND(CODE(MID(B8,2,1))>=97,CODE(MID(B8,2,1))<=122),LEFT(B8,2),LEFT(B8,1)) -> Ba | K8: =IF(J8="","",_xlfn.XLOOKUP(TRIM(J8),Metallic_Radius_Table!A:A,Metallic_Radius_Table!B:B)) -> 2.17 | L8: =IF(ISNUMBER(SEARCH("La",B8)),"La", IF(ISNUMBER(SEARCH("Nd",B8)),"Nd", IF(ISNUMBER(SEARCH("Eu",B8)),"Eu", IF(ISNUMBER(SEARCH("Gd",B8)),"Gd","")))) | M8: =IF(L8="","",_xlfn.XLOOKUP(TRIM(L8),Metallic_Radius_Table!A:A,Metallic_Radius_Table!B:B)) | N8: =TRIM(LEFT(C8,FIND(",",C8)-1)) -> Cr | O8: =IF(N8="","",_xlfn.XLOOKUP(TRIM(N8),Metallic_Radius_Table!A:A,Metallic_Radius_Table!B:B)) -> 1.28 | P8: =TRIM(MID(C8,FIND(",",C8)+1,5)) -> Mo | Q8: =IF(P8="","",_xlfn.XLOOKUP(TRIM(P8),Metallic_Radius_Table!A:A,Metallic_Radius_Table!B:B)) -> 1.39 | R8: =IF(G8>=1, "Ferromagnetic / Ferrimagnetic", IF(G8>=0.05, "Paramagnetic / Weakly magnetic", "Antiferromagnetic / Diamagnetic")) -> Antiferromagnetic / Diamagnetic | U8: =IF(G8>=1, "FM → PM (Curie-type)", IF(G8<0.05, "AFM → PM (Néel-type)", "No long-range magnetic transition")) -> AFM → PM (Néel-type)
A9: mp-1277787 | B9: Ba2FeMoO6 | C9: Fe, Mo | D9: -2.5002732 | E9: 0.000837423 | F9: 0.8641 | G9: 3.2e-06 | H9: C2/m | I9: =TRUE() -> TRUE | J9: =IF(AND(CODE(MID(B9,2,1))>=97,CODE(MID(B9,2,1))<=122),LEFT(B9,2),LEFT(B9,1)) -> Ba | K9: =IF(J9="","",_xlfn.XLOOKUP(TRIM(J9),Metallic_Radius_Table!A:A,Metallic_Radius_Table!B:B)) -> 2.17 | L9: =IF(ISNUMBER(SEARCH("La",B9)),"La", IF(ISNUMBER(SEARCH("Nd",B9)),"Nd", IF(ISNUMBER(SEARCH("Eu",B9)),"Eu", IF(ISNUMBER(SEARCH("Gd",B9)),"Gd","")))) | M9: =IF(L9="","",_xlfn.XLOOKUP(TRIM(L9),Metallic_Radius_Table!A:A,Metallic_Radius_Table!B:B)) | N9: =TRIM(LEFT(C9,FIND(",",C9)-1)) -> Fe | O9: =IF(N9="","",_xlfn.XLOOKUP(TRIM(N9),Metallic_Radius_Table!A:A,Metallic_Radius_Table!B:B)) -> 1.26 | P9: =TRIM(MID(C9,FIND(",",C9)+1,5)) -> Mo | Q9: =IF(P9="","",_xlfn.XLOOKUP(TRIM(P9),Metallic_Radius_Table!A:A,Metallic_Radius_Table!B:B)) -> 1.39 | R9: =IF(G9>=1, "Ferromagnetic / Ferrimagnetic", IF(G9>=0.05, "Paramagnetic / Weakly magnetic", "Antiferromagnetic / Diamagnetic")) -> Antiferromagnetic / Diamagnetic | U9: =IF(G9>=1, "FM → PM (Curie-type)", IF(G9<0.05, "AFM → PM (Néel-type)", "No long-range magnetic transition")) -> AFM → PM (Néel-type)
A10: mp-1288525 | B10: Ba2FeMoO6 | C10: Fe, Mo | D10: -2.5009826 | E10: 0.0001280155 | F10: 0.7715 | G10: 2.00003 | H10: C2 | I10: =TRUE() -> TRUE | J10: =IF(AND(CODE(MID(B10,2,1))>=97,CODE(MID(B10,2,1))<=122),LEFT(B10,2),LEFT(B10,1)) -> Ba | K10: =IF(J10="","",_xlfn.XLOOKUP(TRIM(J10),Metallic_Radius_Table!A:A,Metallic_Radius_Table!B:B)) -> 2.17 | L10: =IF(ISNUMBER(SEARCH("La",B10)),"La", IF(ISNUMBER(SEARCH("Nd",B10)),"Nd", IF(ISNUMBER(SEARCH("Eu",B10)),"Eu", IF(ISNUMBER(SEARCH("Gd",B10)),"Gd","")))) | M10: =IF(L10="","",_xlfn.XLOOKUP(TRIM(L10),Metallic_Radius_Table!A:A,Metallic_Radius_Table!B:B)) | N10: =TRIM(LEFT(C10,FIND(",",C10)-1)) -> Fe | O10: =IF(N10="","",_xlfn.XLOOKUP(TRIM(N10),Metallic_Radius_Table!A:A,Metallic_Radius_Table!B:B)) -> 1.26 | P10: =TRIM(MID(C10,FIND(",",C10)+1,5)) -> Mo | Q10: =IF(P10="","",_xlfn.XLOOKUP(TRIM(P10),Metallic_Radius_Table!A:A,Metallic_Radius_Table!B:B)) -> 1.39 | R10: =IF(G10>=1, "Ferromagnetic / Ferrimagnetic", IF(G10>=0.05, "Paramagnetic / Weakly magnetic", "Antiferromagnetic / Diamagnetic")) -> Ferromagnetic / Ferrimagnetic | U10: =IF(G10>=1, "FM → PM (Curie-type)", IF(G10<0.05, "AFM → PM (Néel-type)", "No long-range magnetic transition")) -> FM → PM (Curie-type)
A11: mp-1288978 | B11: Ba2FeMoO6 | C11: Fe, Mo | D11: -2.5011106 | E11: 0 | F11: 0.9037 | G11: 2.00003 | H11: C2 | I11: =TRUE() -> TRUE | J11: =IF(AND(CODE(MID(B11,2,1))>=97,CODE(MID(B11,2,1))<=122),LEFT(B11,2),LEFT(B11,1)) -> Ba | K11: =IF(J11="","",_xlfn.XLOOKUP(TRIM(J11),Metallic_Radius_Table!A:A,Metallic_Radius_Table!B:B)) -> 2.17 | L11: =IF(ISNUMBER(SEARCH("La",B11)),"La", IF(ISNUMBER(SEARCH("Nd",B11)),"Nd", IF(ISNUMBER(SEARCH("Eu",B11)),"Eu", IF(ISNUMBER(SEARCH("Gd",B11)),"Gd","")))) | M11: =IF(L11="","",_xlfn.XLOOKUP(TRIM(L11),Metallic_Radius_Table!A:A,Metallic_Radius_Table!B:B)) | N11: =TRIM(LEFT(C11,FIND(",",C11)-1)) -> Fe | O11: =IF(N11="","",_xlfn.XLOOKUP(TRIM(N11),Metallic_Radius_Table!A:A,Metallic_Radius_Table!B:B)) -> 1.26 | P11: =TRIM(MID(C11,FIND(",",C11)+1,5)) -> Mo | Q11: =IF(P11="","",_xlfn.XLOOKUP(TRIM(P11),Metallic_Radius_Table!A:A,Metallic_Radius_Table!B:B)) -> 1.39 | R11: =IF(G11>=1, "Ferromagnetic / Ferrimagnetic", IF(G11>=0.05, "Paramagnetic / Weakly magnetic", "Antiferromagnetic / Diamagnetic")) -> Ferromagnetic / Ferrimagnetic | U11: =IF(G11>=1, "FM → PM (Curie-type)", IF(G11<0.05, "AFM → PM (Néel-type)", "No long-range magnetic transition")) -> FM → PM (Curie-type)
A12: mp-18995 | B12: Ba2FeMoO6 | C12: Fe, Mo | D12: -2.4978201 | E12: 0.003290486 | F12: 0 | G12: 3.9999999 | H12: C2/m | I12: =TRUE() -> TRUE | J12: =IF(AND(CODE(MID(B12,2,1))>=97,CODE(MID(B12,2,1))<=122),LEFT(B12,2),LEFT(B12,1)) -> Ba | K12: =IF(J12="","",_xlfn.XLOOKUP(TRIM(J12),Metallic_Radius_Table!A:A,Metallic_Radius_Table!B:B)) -> 2.17 | L12: =IF(ISNUMBER(SEARCH("La",B12)),"La", IF(ISNUMBER(SEARCH("Nd",B12)),"Nd", IF(ISNUMBER(SEARCH("Eu",B12)),"Eu", IF(ISNUMBER(SEARCH("Gd",B12)),"Gd","")))) | M12: =IF(L12="","",_xlfn.XLOOKUP(TRIM(L12),Metallic_Radius_Table!A:A,Metallic_Radius_Table!B:B)) | N12: =TRIM(LEFT(C12,FIND(",",C12)-1)) -> Fe | O12: =IF(N12="","",_xlfn.XLOOKUP(TRIM(N12),Metallic_Radius_Table!A:A,Metallic_Radius_Table!B:B)) -> 1.26 | P12: =TRIM(MID(C12,FIND(",",C12)+1,5)) -> Mo | Q12: =IF(P12="","",_xlfn.XLOOKUP(TRIM(P12),Metallic_Radius_Table!A:A,Metallic_Radius_Table!B:B)) -> 1.39 | R12: =IF(G12>=1, "Ferromagnetic / Ferrimagnetic", IF(G12>=0.05, "Paramagnetic / Weakly magnetic", "Antiferromagnetic / Diamagnetic")) -> Ferromagnetic / Ferrimagnetic | U12: =IF(G12>=1, "FM → PM (Curie-type)", IF(G12<0.05, "AFM → PM (Néel-type)", "No long-range magnetic transition")) -> FM → PM (Curie-type)
A13: mp-31756 | B13: Ba2FeReO6 | C13: Re, Fe | D13: -2.4859155 | E13: 0.0030492895 | F13: 0 | G13: 3.000002 | H13: Fm-3m | I13: =TRUE() -> TRUE | J13: =IF(AND(CODE(MID(B13,2,1))>=97,CODE(MID(B13,2,1))<=122),LEFT(B13,2),LEFT(B13,1)) -> Ba | K13: =IF(J13="","",_xlfn.XLOOKUP(TRIM(J13),Metallic_Radius_Table!A:A,Metallic_Radius_Table!B:B)) -> 2.17 | L13: =IF(ISNUMBER(SEARCH("La",B13)),"La", IF(ISNUMBER(SEARCH("Nd",B13)),"Nd", IF(ISNUMBER(SEARCH("Eu",B13)),"Eu", IF(ISNUMBER(SEARCH("Gd",B13)),"Gd","")))) | M13: =IF(L13="","",_xlfn.XLOOKUP(TRIM(L13),Metallic_Radius_Table!A:A,Metallic_Radius_Table!B:B)) | N13: =TRIM(LEFT(C13,FIND(",",C13)-1)) -> Re | O13: =IF(N13="","",_xlfn.XLOOKUP(TRIM(N13),Metallic_Radius_Table!A:A,Metallic_Radius_Table!B:B)) -> 1.37 | P13: =TRIM(MID(C13,FIND(",",C13)+1,5)) -> Fe | Q13: =IF(P13="","",_xlfn.XLOOKUP(TRIM(P13),Metallic_Radius_Table!A:A,Metallic_Radius_Table!B:B)) -> 1.26 | R13: =IF(G13>=1, "Ferromagnetic / Ferrimagnetic", IF(G13>=0.05, "Paramagnetic / Weakly magnetic", "Antiferromagnetic / Diamagnetic")) -> Ferromagnetic / Ferrimagnetic | U13: =IF(G13>=1, "FM → PM (Curie-type)", IF(G13<0.05, "AFM → PM (Néel-type)", "No long-range magnetic transition")) -> FM → PM (Curie-type)
... A72: mp-1227378 | B72: BaTiMnBiO6 | C72: Mn, Ti | D72: -2.4950508 | E72: 0.16815272 | F72: 0 | G72: 4.0101239 | H72: F-43m | I72: =TRUE() -> TRUE | J72: =IF(AND(CODE(MID(B72,2,1))>=97,CODE(MID(B72,2,1))<=122),LEFT(B72,2),LEFT(B72,1)) -> Ba | K72: =IF(J72="","",_xlfn.XLOOKUP(TRIM(J72),Metallic_Radius_Table!A:A,Metallic_Radius_Table!B:B)) -> 2.17 | L72: =IF(ISNUMBER(SEARCH("La",B72)),"La", IF(ISNUMBER(SEARCH("Nd",B72)),"Nd", IF(ISNUMBER(SEARCH("Eu",B72)),"Eu", IF(ISNUMBER(SEARCH("Gd",B72)),"Gd","")))) | M72: =IF(L72="","",_xlfn.XLOOKUP(TRIM(L72),Metallic_Radius_Table!A:A,Metallic_Radius_Table!B:B)) | N72: =TRIM(LEFT(C72,FIND(",",C72)-1)) -> Mn | O72: =IF(N72="","",_xlfn.XLOOKUP(TRIM(N72),Metallic_Radius_Table!A:A,Metallic_Radius_Table!B:B)) -> 1.27 | P72: =TRIM(MID(C72,FIND(",",C72)+1,5)) -> Ti | Q72: =IF(P72="","",_xlfn.XLOOKUP(TRIM(P72),Metallic_Radius_Table!A:A,Metallic_Radius_Table!B:B)) -> 1.47 | R72: =IF(G72>=1, "Ferromagnetic / Ferrimagnetic", IF(G72>=0.05, "Paramagnetic / Weakly magnetic", "Antiferromagnetic / Diamagnetic")) -> Ferromagnetic / Ferrimagnetic | U72: =IF(G72>=1, "FM → PM (Curie-type)", IF(G72<0.05, "AFM → PM (Néel-type)", "No long-range magnetic transition")) -> FM → PM (Curie-type)
A73: mp-1516399 | B73: BaTiMnNbO6 | C73: Mn, Nb, Ti | D73: -2.8739686 | E73: 0.195678 | F73: 0 | G73: 4.9234599 | H73: F-43m | I73: =TRUE() -> TRUE | J73: =IF(AND(CODE(MID(B73,2,1))>=97,CODE(MID(B73,2,1))<=122),LEFT(B73,2),LEFT(B73,1)) -> Ba | K73: =IF(J73="","",_xlfn.XLOOKUP(TRIM(J73),Metallic_Radius_Table!A:A,Metallic_Radius_Table!B:B)) -> 2.17 | L73: =IF(ISNUMBER(SEARCH("La",B73)),"La", IF(ISNUMBER(SEARCH("Nd",B73)),"Nd", IF(ISNUMBER(SEARCH("Eu",B73)),"Eu", IF(ISNUMBER(SEARCH("Gd",B73)),"Gd","")))) | M73: =IF(L73="","",_xlfn.XLOOKUP(TRIM(L73),Metallic_Radius_Table!A:A,Metallic_Radius_Table!B:B)) | N73: =TRIM(LEFT(C73,FIND(",",C73)-1)) -> Mn | O73: =IF(N73="","",_xlfn.XLOOKUP(TRIM(N73),Metallic_Radius_Table!A:A,Metallic_Radius_Table!B:B)) -> 1.27 | P73: Nb | Q73: =IF(P73="","",_xlfn.XLOOKUP(TRIM(P73),Metallic_Radius_Table!A:A,Metallic_Radius_Table!B:B)) -> 1.46 | R73: =IF(G73>=1, "Ferromagnetic / Ferrimagnetic", IF(G73>=0.05, "Paramagnetic / Weakly magnetic", "Antiferromagnetic / Diamagnetic")) -> Ferromagnetic / Ferrimagnetic | U73: =IF(G73>=1, "FM → PM (Curie-type)", IF(G73<0.05, "AFM → PM (Néel-type)", "No long-range magnetic transition")) -> FM → PM (Curie-type)
A74: mp-1522797 | B74: BaTiNbGaO6 | C74: Nb, Ti | D74: -2.9035527 | E74: 0.14561911 | F74: 0.6275 | G74: 0 | H74: F-43m | I74: =TRUE() -> TRUE | J74: =IF(AND(CODE(MID(B74,2,1))>=97,CODE(MID(B74,2,1))<=122),LEFT(B74,2),LEFT(B74,1)) -> Ba | K74: =IF(J74="","",_xlfn.XLOOKUP(TRIM(J74),Metallic_Radius_Table!A:A,Metallic_Radius_Table!B:B)) -> 2.17 | L74: =IF(ISNUMBER(SEARCH("La",B74)),"La", IF(ISNUMBER(SEARCH("Nd",B74)),"Nd", IF(ISNUMBER(SEARCH("Eu",B74)),"Eu", IF(ISNUMBER(SEARCH("Gd",B74)),"Gd","")))) | M74: =IF(L74="","",_xlfn.XLOOKUP(TRIM(L74),Metallic_Radius_Table!A:A,Metallic_Radius_Table!B:B)) | N74: =TRIM(LEFT(C74,FIND(",",C74)-1)) -> Nb | O74: =IF(N74="","",_xlfn.XLOOKUP(TRIM(N74),Metallic_Radius_Table!A:A,Metallic_Radius_Table!B:B)) -> 1.46 | P74: =TRIM(MID(C74,FIND(",",C74)+1,5)) -> Ti | Q74: =IF(P74="","",_xlfn.XLOOKUP(TRIM(P74),Metallic_Radius_Table!A:A,Metallic_Radius_Table!B:B)) -> 1.47 | R74: =IF(G74>=1, "Ferromagnetic / Ferrimagnetic", IF(G74>=0.05, "Paramagnetic / Weakly magnetic", "Antiferromagnetic / Diamagnetic")) -> Antiferromagnetic / Diamagnetic | U74: =IF(G74>=1, "FM → PM (Curie-type)", IF(G74<0.05, "AFM → PM (Néel-type)", "No long-range magnetic transition")) -> AFM → PM (Néel-type)
A75: mp-1518364 | B75: BaVInWO6 | C75: V, W | D75: -2.2842285 | E75: 0.16324199 | F75: 0 | G75: 2.0421198 | H75: F-43m | I75: =TRUE() -> TRUE | J75: =IF(AND(CODE(MID(B75,2,1))>=97,CODE(MID(B75,2,1))<=122),LEFT(B75,2),LEFT(B75,1)) -> Ba | K75: =IF(J75="","",_xlfn.XLOOKUP(TRIM(J75),Metallic_Radius_Table!A:A,Metallic_Radius_Table!B:B)) -> 2.17 | L75: =IF(ISNUMBER(SEARCH("La",B75)),"La", IF(ISNUMBER(SEARCH("Nd",B75)),"Nd", IF(ISNUMBER(SEARCH("Eu",B75)),"Eu", IF(ISNUMBER(SEARCH("Gd",B75)),"Gd","")))) | M75: =IF(L75="","",_xlfn.XLOOKUP(TRIM(L75),Metallic_Radius_Table!A:A,Metallic_Radius_Table!B:B)) | N75: =TRIM(LEFT(C75,FIND(",",C75)-1)) -> V | O75: =IF(N75="","",_xlfn.XLOOKUP(TRIM(N75),Metallic_Radius_Table!A:A,Metallic_Radius_Table!B:B)) -> 1.34 | P75: =TRIM(MID(C75,FIND(",",C75)+1,5)) -> W | Q75: =IF(P75="","",_xlfn.XLOOKUP(TRIM(P75),Metallic_Radius_Table!A:A,Metallic_Radius_Table!B:B)) -> 1.41 | R75: =IF(G75>=1, "Ferromagnetic / Ferrimagnetic", IF(G75>=0.05, "Paramagnetic / Weakly magnetic", "Antiferromagnetic / Diamagnetic")) -> Ferromagnetic / Ferrimagnetic | U75: =IF(G75>=1, "FM → PM (Curie-type)", IF(G75<0.05, "AFM → PM (Néel-type)", "No long-range magnetic transition")) -> FM → PM (Curie-type)
A76: mp-1517252 | B76: BaZrNbInO6 | C76: Zr, Nb | D76: -3.0013979 | E76: 0.099896537 | F76: 0.6061 | G76: 0 | H76: F-43m | I76: =TRUE() -> TRUE | J76: =IF(AND(CODE(MID(B76,2,1))>=97,CODE(MID(B76,2,1))<=122),LEFT(B76,2),LEFT(B76,1)) -> Ba | K76: =IF(J76="","",_xlfn.XLOOKUP(TRIM(J76),Metallic_Radius_Table!A:A,Metallic_Radius_Table!B:B)) -> 2.17 | L76: =IF(ISNUMBER(SEARCH("La",B76)),"La", IF(ISNUMBER(SEARCH("Nd",B76)),"Nd", IF(ISNUMBER(SEARCH("Eu",B76)),"Eu", IF(ISNUMBER(SEARCH("Gd",B76)),"Gd","")))) | M76: =IF(L76="","",_xlfn.XLOOKUP(TRIM(L76),Metallic_Radius_Table!A:A,Metallic_Radius_Table!B:B)) | N76: =TRIM(LEFT(C76,FIND(",",C76)-1)) -> Zr | O76: =IF(N76="","",_xlfn.XLOOKUP(TRIM(N76),Metallic_Radius_Table!A:A,Metallic_Radius_Table!B:B)) -> 1.6 | P76: =TRIM(MID(C76,FIND(",",C76)+1,5)) -> Nb | Q76: =IF(P76="","",_xlfn.XLOOKUP(TRIM(P76),Metallic_Radius_Table!A:A,Metallic_Radius_Table!B:B)) -> 1.46 | R76: =IF(G76>=1, "Ferromagnetic / Ferrimagnetic", IF(G76>=0.05, "Paramagnetic / Weakly magnetic", "Antiferromagnetic / Diamagnetic")) -> Antiferromagnetic / Diamagnetic | U76: =IF(G76>=1, "FM → PM (Curie-type)", IF(G76<0.05, "AFM → PM (Néel-type)", "No long-range magnetic transition")) -> AFM → PM (Néel-type)
A77: mp-1517256 | B77: BaZrTiInO6 | C77: Zr, Ti | D77: -3.0284367 | E77: 0.19860489 | F77: 0 | G77: 5.02e-05 | H77: F-43m | I77: =TRUE() -> TRUE | J77: =IF(AND(CODE(MID(B77,2,1))>=97,CODE(MID(B77,2,1))<=122),LEFT(B77,2),LEFT(B77,1)) -> Ba | K77: =IF(J77="","",_xlfn.XLOOKUP(TRIM(J77),Metallic_Radius_Table!A:A,Metallic_Radius_Table!B:B)) -> 2.17 | L77: =IF(ISNUMBER(SEARCH("La",B77)),"La", IF(ISNUMBER(SEARCH("Nd",B77)),"Nd", IF(ISNUMBER(SEARCH("Eu",B77)),"Eu", IF(ISNUMBER(SEARCH("Gd",B77)),"Gd","")))) | M77: =IF(L77="","",_xlfn.XLOOKUP(TRIM(L77),Metallic_Radius_Table!A:A,Metallic_Radius_Table!B:B)) | N77: =TRIM(LEFT(C77,FIND(",",C77)-1)) -> Zr | O77: =IF(N77="","",_xlfn.XLOOKUP(TRIM(N77),Metallic_Radius_Table!A:A,Metallic_Radius_Table!B:B)) -> 1.6 | P77: =TRIM(MID(C77,FIND(",",C77)+1,5)) -> Ti | Q77: =IF(P77="","",_xlfn.XLOOKUP(TRIM(P77),Metallic_Radius_Table!A:A,Metallic_Radius_Table!B:B)) -> 1.47 | R77: =IF(G77>=1, "Ferromagnetic / Ferrimagnetic", IF(G77>=0.05, "Paramagnetic / Weakly magnetic", "Antiferromagnetic / Diamagnetic")) -> Antiferromagnetic / Diamagnetic | U77: =IF(G77>=1, "FM → PM (Curie-type)", IF(G77<0.05, "AFM → PM (Néel-type)", "No long-range magnetic transition")) -> AFM → PM (Néel-type)
A78: mp-20286 | B78: Ba2ReNiO6 | C78: Re, Ni | D78: -2.4419068 | E78: 0.033321185 | F78: 0 | G78: 3.0213158 | H78: Fm-3m | I78: =TRUE() -> TRUE | J78: =IF(AND(CODE(MID(B78,2,1))>=97,CODE(MID(B78,2,1))<=122),LEFT(B78,2),LEFT(B78,1)) -> Ba | K78: =IF(J78="","",_xlfn.XLOOKUP(TRIM(J78),Metallic_Radius_Table!A:A,Metallic_Radius_Table!B:B)) -> 2.17 | L78: =IF(ISNUMBER(SEARCH("La",B78)),"La", IF(ISNUMBER(SEARCH("Nd",B78)),"Nd", IF(ISNUMBER(SEARCH("Eu",B78)),"Eu", IF(ISNUMBER(SEARCH("Gd",B78)),"Gd","")))) | M78: =IF(L78="","",_xlfn.XLOOKUP(TRIM(L78),Metallic_Radius_Table!A:A,Metallic_Radius_Table!B:B)) | N78: =TRIM(LEFT(C78,FIND(",",C78)-1)) -> Re | O78: =IF(N78="","",_xlfn.XLOOKUP(TRIM(N78),Metallic_Radius_Table!A:A,Metallic_Radius_Table!B:B)) -> 1.37 | P78: =TRIM(MID(C78,FIND(",",C78)+1,5)) -> Ni | Q78: =IF(P78="","",_xlfn.XLOOKUP(TRIM(P78),Metallic_Radius_Table!A:A,Metallic_Radius_Table!B:B)) -> 1.24 | R78: =IF(G78>=1, "Ferromagnetic / Ferrimagnetic", IF(G78>=0.05, "Paramagnetic / Weakly magnetic", "Antiferromagnetic / Diamagnetic")) -> Ferromagnetic / Ferrimagnetic | U78: =IF(G78>=1, "FM → PM (Curie-type)", IF(G78<0.05, "AFM → PM (Néel-type)", "No long-range magnetic transition")) -> FM → PM (Curie-type)
A79: mp-1228308 | B79: Ba2TaCoO6 | C79: Co, Ta | D79: -2.8117528 | E79: 0.073295865 | F79: 1.5328 | G79: 1.21e-05 | H79: Fm-3m | I79: =TRUE() -> TRUE | J79: =IF(AND(CODE(MID(B79,2,1))>=97,CODE(MID(B79,2,1))<=122),LEFT(B79,2),LEFT(B79,1)) -> Ba | K79: =IF(J79="","",_xlfn.XLOOKUP(TRIM(J79),Metallic_Radius_Table!A:A,Metallic_Radius_Table!B:B)) -> 2.17 | L79: =IF(ISNUMBER(SEARCH("La",B79)),"La", IF(ISNUMBER(SEARCH("Nd",B79)),"Nd", IF(ISNUMBER(SEARCH("Eu",B79)),"Eu", IF(ISNUMBER(SEARCH("Gd",B79)),"Gd","")))) | M79: =IF(L79="","",_xlfn.XLOOKUP(TRIM(L79),Metallic_Radius_Table!A:A,Metallic_Radius_Table!B:B)) | N79: =TRIM(LEFT(C79,FIND(",",C79)-1)) -> Co | O79: =IF(N79="","",_xlfn.XLOOKUP(TRIM(N79),Metallic_Radius_Table!A:A,Metallic_Radius_Table!B:B)) -> 1.25 | P79: =TRIM(MID(C79,FIND(",",C79)+1,5)) -> Ta | Q79: =IF(P79="","",_xlfn.XLOOKUP(TRIM(P79),Metallic_Radius_Table!A:A,Metallic_Radius_Table!B:B)) -> 1.46 | R79: =IF(G79>=1, "Ferromagnetic / Ferrimagnetic", IF(G79>=0.05, "Paramagnetic / Weakly magnetic", "Antiferromagnetic / Diamagnetic")) -> Antiferromagnetic / Diamagnetic | U79: =IF(G79>=1, "FM → PM (Curie-type)", IF(G79<0.05, "AFM → PM (Néel-type)", "No long-range magnetic transition")) -> AFM → PM (Néel-type)
A80: mp-31630 | B80: Ba2TaCrO6 | C80: Cr, Ta | D80: -3.1679102 | E80: 0 | F80: 2.2009 | G80: 12.000559 | H80: P6_3/mmc | I80: =TRUE() -> TRUE | J80: =IF(AND(CODE(MID(B80,2,1))>=97,CODE(MID(B80,2,1))<=122),LEFT(B80,2),LEFT(B80,1)) -> Ba | K80: =IF(J80="","",_xlfn.XLOOKUP(TRIM(J80),Metallic_Radius_Table!A:A,Metallic_Radius_Table!B:B)) -> 2.17 | L80: =IF(ISNUMBER(SEARCH("La",B80)),"La", IF(ISNUMBER(SEARCH("Nd",B80)),"Nd", IF(ISNUMBER(SEARCH("Eu",B80)),"Eu", IF(ISNUMBER(SEARCH("Gd",B80)),"Gd","")))) | M80: =IF(L80="","",_xlfn.XLOOKUP(TRIM(L80),Metallic_Radius_Table!A:A,Metallic_Radius_Table!B:B)) | N80: =TRIM(LEFT(C80,FIND(",",C80)-1)) -> Cr | O80: =IF(N80="","",_xlfn.XLOOKUP(TRIM(N80),Metallic_Radius_Table!A:A,Metallic_Radius_Table!B:B)) -> 1.28 | P80: =TRIM(MID(C80,FIND(",",C80)+1,5)) -> Ta | Q80: =IF(P80="","",_xlfn.XLOOKUP(TRIM(P80),Metallic_Radius_Table!A:A,Metallic_Radius_Table!B:B)) -> 1.46 | R80: =IF(G80>=1, "Ferromagnetic / Ferrimagnetic", IF(G80>=0.05, "Paramagnetic / Weakly magnetic", "Antiferromagnetic / Diamagnetic")) -> Ferromagnetic / Ferrimagnetic | U80: =IF(G80>=1, "FM → PM (Curie-type)", IF(G80<0.05, "AFM → PM (Néel-type)", "No long-range magnetic transition")) -> FM → PM (Curie-type)
A81: mp-1205671 | B81: Ba2TaFeO6 | C81: Fe, Ta | D81: -3.0062139 | E81: 0 | F81: 1.8623 | G81: 0 | H81: Fm-3m | I81: =TRUE() -> TRUE | J81: =IF(AND(CODE(MID(B81,2,1))>=97,CODE(MID(B81,2,1))<=122),LEFT(B81,2),LEFT(B81,1)) -> Ba | K81: =IF(J81="","",_xlfn.XLOOKUP(TRIM(J81),Metallic_Radius_Table!A:A,Metallic_Radius_Table!B:B)) -> 2.17 | L81: =IF(ISNUMBER(SEARCH("La",B81)),"La", IF(ISNUMBER(SEARCH("Nd",B81)),"Nd", IF(ISNUMBER(SEARCH("Eu",B81)),"Eu", IF(ISNUMBER(SEARCH("Gd",B81)),"Gd","")))) | M81: =IF(L81="","",_xlfn.XLOOKUP(TRIM(L81),Metallic_Radius_Table!A:A,Metallic_Radius_Table!B:B)) | N81: =TRIM(LEFT(C81,FIND(",",C81)-1)) -> Fe | O81: =IF(N81="","",_xlfn.XLOOKUP(TRIM(N81),Metallic_Radius_Table!A:A,Metallic_Radius_Table!B:B)) -> 1.26 | P81: =TRIM(MID(C81,FIND(",",C81)+1,5)) -> Ta | Q81: =IF(P81="","",_xlfn.XLOOKUP(TRIM(P81),Metallic_Radius_Table!A:A,Metallic_Radius_Table!B:B)) -> 1.46 | R81: =IF(G81>=1, "Ferromagnetic / Ferrimagnetic", IF(G81>=0.05, "Paramagnetic / Weakly magnetic", "Antiferromagnetic / Diamagnetic")) -> Antiferromagnetic / Diamagnetic | U81: =IF(G81>=1, "FM → PM (Curie-type)", IF(G81<0.05, "AFM → PM (Néel-type)", "No long-range magnetic transition")) -> AFM → PM (Néel-type)
A82: mp-1228319 | B82: Ba2TaMnO6 | C82: Ta, Mn | D82: -3.0490525 | E82: 0.02853079 | F82: 0 | G82: 4.0000375 | H82: Fm-3m | I82: =TRUE() -> TRUE | J82: =IF(AND(CODE(MID(B82,2,1))>=97,CODE(MID(B82,2,1))<=122),LEFT(B82,2),LEFT(B82,1)) -> Ba | K82: =IF(J82="","",_xlfn.XLOOKUP(TRIM(J82),Metallic_Radius_Table!A:A,Metallic_Radius_Table!B:B)) -> 2.17 | L82: =IF(ISNUMBER(SEARCH("La",B82)),"La", IF(ISNUMBER(SEARCH("Nd",B82)),"Nd", IF(ISNUMBER(SEARCH("Eu",B82)),"Eu", IF(ISNUMBER(SEARCH("Gd",B82)),"Gd","")))) | M82: =IF(L82="","",_xlfn.XLOOKUP(TRIM(L82),Metallic_Radius_Table!A:A,Metallic_Radius_Table!B:B)) | N82: =TRIM(LEFT(C82,FIND(",",C82)-1)) -> Ta | O82: =IF(N82="","",_xlfn.XLOOKUP(TRIM(N82),Metallic_Radius_Table!A:A,Metallic_Radius_Table!B:B)) -> 1.46 | P82: =TRIM(MID(C82,FIND(",",C82)+1,5)) -> Mn | Q82: =IF(P82="","",_xlfn.XLOOKUP(TRIM(P82),Metallic_Radius_Table!A:A,Metallic_Radius_Table!B:B)) -> 1.27 | R82: =IF(G82>=1, "Ferromagnetic / Ferrimagnetic", IF(G82>=0.05, "Paramagnetic / Weakly magnetic", "Antiferromagnetic / Diamagnetic")) -> Ferromagnetic / Ferrimagnetic | U82: =IF(G82>=1, "FM → PM (Curie-type)", IF(G82<0.05, "AFM → PM (Néel-type)", "No long-range magnetic transition")) -> FM → PM (Curie-type)
A83: mp-1291775 | B83: Ba2TaMnO6 | C83: Ta, Mn | D83: -3.070836 | E83: 0.0067472199 | F83: 1.1823 | G83: 16.000382 | H83: Pnma | I83: =TRUE() -> TRUE | J83: =IF(AND(CODE(MID(B83,2,1))>=97,CODE(MID(B83,2,1))<=122),LEFT(B83,2),LEFT(B83,1)) -> Ba | K83: =IF(J83="","",_xlfn.XLOOKUP(TRIM(J83),Metallic_Radius_Table!A:A,Metallic_Radius_Table!B:B)) -> 2.17 | L83: =IF(ISNUMBER(SEARCH("La",B83)),"La", IF(ISNUMBER(SEARCH("Nd",B83)),"Nd", IF(ISNUMBER(SEARCH("Eu",B83)),"Eu", IF(ISNUMBER(SEARCH("Gd",B83)),"Gd","")))) | M83: =IF(L83="","",_xlfn.XLOOKUP(TRIM(L83),Metallic_Radius_Table!A:A,Metallic_Radius_Table!B:B)) | N83: =TRIM(LEFT(C83,FIND(",",C83)-1)) -> Ta | O83: =IF(N83="","",_xlfn.XLOOKUP(TRIM(N83),Metallic_Radius_Table!A:A,Metallic_Radius_Table!B:B)) -> 1.46 | P83: =TRIM(MID(C83,FIND(",",C83)+1,5)) -> Mn | Q83: =IF(P83="","",_xlfn.XLOOKUP(TRIM(P83),Metallic_Radius_Table!A:A,Metallic_Radius_Table!B:B)) -> 1.27 | R83: =IF(G83>=1, "Ferromagnetic / Ferrimagnetic", IF(G83>=0.05, "Paramagnetic / Weakly magnetic", "Antiferromagnetic / Diamagnetic")) -> Ferromagnetic / Ferrimagnetic | U83: =IF(G83>=1, "FM → PM (Curie-type)", IF(G83<0.05, "AFM → PM (Néel-type)", "No long-range magnetic transition")) -> FM → PM (Curie-type)
A84: mp-1307944 | B84: Ba2TaMnO6 | C84: Ta, Mn | D84: -3.069907 | E84: 0.0076762114 | F84: 1.1315 | G84: 16.000401 | H84: P1 | I84: =TRUE() -> TRUE | J84: =IF(AND(CODE(MID(B84,2,1))>=97,CODE(MID(B84,2,1))<=122),LEFT(B84,2),LEFT(B84,1)) -> Ba | K84: =IF(J84="","",_xlfn.XLOOKUP(TRIM(J84),Metallic_Radius_Table!A:A,Metallic_Radius_Table!B:B)) -> 2.17 | L84: =IF(ISNUMBER(SEARCH("La",B84)),"La", IF(ISNUMBER(SEARCH("Nd",B84)),"Nd", IF(ISNUMBER(SEARCH("Eu",B84)),"Eu", IF(ISNUMBER(SEARCH("Gd",B84)),"Gd","")))) | M84: =IF(L84="","",_xlfn.XLOOKUP(TRIM(L84),Metallic_Radius_Table!A:A,Metallic_Radius_Table!B:B)) | N84: =TRIM(LEFT(C84,FIND(",",C84)-1)) -> Ta | O84: =IF(N84="","",_xlfn.XLOOKUP(TRIM(N84),Metallic_Radius_Table!A:A,Metallic_Radius_Table!B:B)) -> 1.46 | P84: =TRIM(MID(C84,FIND(",",C84)+1,5)) -> Mn | Q84: =IF(P84="","",_xlfn.XLOOKUP(TRIM(P84),Metallic_Radius_Table!A:A,Metallic_Radius_Table!B:B)) -> 1.27 | R84: =IF(G84>=1, "Ferromagnetic / Ferrimagnetic", IF(G84>=0.05, "Paramagnetic / Weakly magnetic", "Antiferromagnetic / Diamagnetic")) -> Ferromagnetic / Ferrimagnetic | U84: =IF(G84>=1, "FM → PM (Curie-type)", IF(G84<0.05, "AFM → PM (Néel-type)", "No long-range magnetic transition")) -> FM → PM (Curie-type)
A85: mp-1309882 | B85: Ba2TaMnO6 | C85: Ta, Mn | D85: -3.071425 | E85: 0.0061582344 | F85: 1.1694 | G85: 8.5e-06 | H85: I4/mmm | I85: =TRUE() -> TRUE | J85: =IF(AND(CODE(MID(B85,2,1))>=97,CODE(MID(B85,2,1))<=122),LEFT(B85,2),LEFT(B85,1)) -> Ba | K85: =IF(J85="","",_xlfn.XLOOKUP(TRIM(J85),Metallic_Radius_Table!A:A,Metallic_Radius_Table!B:B)) -> 2.17 | L85: =IF(ISNUMBER(SEARCH("La",B85)),"La", IF(ISNUMBER(SEARCH("Nd",B85)),"Nd", IF(ISNUMBER(SEARCH("Eu",B85)),"Eu", IF(ISNUMBER(SEARCH("Gd",B85)),"Gd","")))) | M85: =IF(L85="","",_xlfn.XLOOKUP(TRIM(L85),Metallic_Radius_Table!A:A,Metallic_Radius_Table!B:B)) | N85: =TRIM(LEFT(C85,FIND(",",C85)-1)) -> Ta | O85: =IF(N85="","",_xlfn.XLOOKUP(TRIM(N85),Metallic_Radius_Table!A:A,Metallic_Radius_Table!B:B)) -> 1.46 | P85: =TRIM(MID(C85,FIND(",",C85)+1,5)) -> Mn | Q85: =IF(P85="","",_xlfn.XLOOKUP(TRIM(P85),Metallic_Radius_Table!A:A,Metallic_Radius_Table!B:B)) -> 1.27 | R85: =IF(G85>=1, "Ferromagnetic / Ferrimagnetic", IF(G85>=0.05, "Paramagnetic / Weakly magnetic", "Antiferromagnetic / Diamagnetic")) -> Antiferromagnetic / Diamagnetic | U85: =IF(G85>=1, "FM → PM (Curie-type)", IF(G85<0.05, "AFM → PM (Néel-type)", "No long-range magnetic transition")) -> AFM → PM (Néel-type)
... A411: mp-1216838 | B411: TiNbBiO6 | C411: Nb, Ti | D411: -2.8459842 | E411: 0.0041209439 | F411: 2.3865 | G411: 2.2e-06 | H411: P1 | I411: =TRUE() -> TRUE | J411: =IF(AND(CODE(MID(B411,2,1))>=97,CODE(MID(B411,2,1))<=122),LEFT(B411,2),LEFT(B411,1)) -> Ti | K411: =IF(J411="","",_xlfn.XLOOKUP(TRIM(J411),Metallic_Radius_Table!A:A,Metallic_Radius_Table!B:B)) -> 1.47 | L411: =IF(ISNUMBER(SEARCH("La",B411)),"La", IF(ISNUMBER(SEARCH("Nd",B411)),"Nd", IF(ISNUMBER(SEARCH("Eu",B411)),"Eu", IF(ISNUMBER(SEARCH("Gd",B411)),"Gd","")))) | M411: =IF(L411="","",_xlfn.XLOOKUP(TRIM(L411),Metallic_Radius_Table!A:A,Metallic_Radius_Table!B:B)) | N411: =TRIM(LEFT(C411,FIND(",",C411)-1)) -> Nb | O411: =IF(N411="","",_xlfn.XLOOKUP(TRIM(N411),Metallic_Radius_Table!A:A,Metallic_Radius_Table!B:B)) -> 1.46 | P411: =TRIM(MID(C411,FIND(",",C411)+1,5)) -> Ti | Q411: =IF(P411="","",_xlfn.XLOOKUP(TRIM(P411),Metallic_Radius_Table!A:A,Metallic_Radius_Table!B:B)) -> 1.47 | R411: =IF(G411>=1, "Ferromagnetic / Ferrimagnetic", IF(G411>=0.05, "Paramagnetic / Weakly magnetic", "Antiferromagnetic / Diamagnetic")) -> Antiferromagnetic / Diamagnetic | U411: =IF(G411>=1, "FM → PM (Curie-type)", IF(G411<0.05, "AFM → PM (Néel-type)", "No long-range magnetic transition")) -> AFM → PM (Néel-type)
A412: mp-1189894 | B412: Y2MnCoO6 | C412: Co, Mn, Y | D412: -2.8346195 | E412: 0 | F412: 0 | G412: 11.995503 | H412: P2_1/c | I412: =TRUE() -> TRUE | J412: =IF(AND(CODE(MID(B412,2,1))>=97,CODE(MID(B412,2,1))<=122),LEFT(B412,2),LEFT(B412,1)) -> Y | K412: =IF(J412="","",_xlfn.XLOOKUP(TRIM(J412),Metallic_Radius_Table!A:A,Metallic_Radius_Table!B:B)) -> 1.8 | L412: =IF(ISNUMBER(SEARCH("La",B412)),"La", IF(ISNUMBER(SEARCH("Nd",B412)),"Nd", IF(ISNUMBER(SEARCH("Eu",B412)),"Eu", IF(ISNUMBER(SEARCH("Gd",B412)),"Gd","")))) | M412: =IF(L412="","",_xlfn.XLOOKUP(TRIM(L412),Metallic_Radius_Table!A:A,Metallic_Radius_Table!B:B)) | N412: =TRIM(LEFT(C412,FIND(",",C412)-1)) -> Co | O412: =IF(N412="","",_xlfn.XLOOKUP(TRIM(N412),Metallic_Radius_Table!A:A,Metallic_Radius_Table!B:B)) -> 1.25 | P412: Mn | Q412: =IF(P412="","",_xlfn.XLOOKUP(TRIM(P412),Metallic_Radius_Table!A:A,Metallic_Radius_Table!B:B)) -> 1.27 | R412: =IF(G412>=1, "Ferromagnetic / Ferrimagnetic", IF(G412>=0.05, "Paramagnetic / Weakly magnetic", "Antiferromagnetic / Diamagnetic")) -> Ferromagnetic / Ferrimagnetic | U412: =IF(G412>=1, "FM → PM (Curie-type)", IF(G412<0.05, "AFM → PM (Néel-type)", "No long-range magnetic transition")) -> FM → PM (Curie-type)
A413: mp-19192 | B413: Y2MnNiO6 | C413: Mn, Ni, Y | D413: -2.8229455 | E413: 0 | F413: 0 | G413: 9.999928 | H413: P2_1/c | I413: =TRUE() -> TRUE | J413: =IF(AND(CODE(MID(B413,2,1))>=97,CODE(MID(B413,2,1))<=122),LEFT(B413,2),LEFT(B413,1)) -> Y | K413: =IF(J413="","",_xlfn.XLOOKUP(TRIM(J413),Metallic_Radius_Table!A:A,Metallic_Radius_Table!B:B)) -> 1.8 | L413: =IF(ISNUMBER(SEARCH("La",B413)),"La", IF(ISNUMBER(SEARCH("Nd",B413)),"Nd", IF(ISNUMBER(SEARCH("Eu",B413)),"Eu", IF(ISNUMBER(SEARCH("Gd",B413)),"Gd","")))) | M413: =IF(L413="","",_xlfn.XLOOKUP(TRIM(L413),Metallic_Radius_Table!A:A,Metallic_Radius_Table!B:B)) | N413: =TRIM(LEFT(C413,FIND(",",C413)-1)) -> Mn | O413: =IF(N413="","",_xlfn.XLOOKUP(TRIM(N413),Metallic_Radius_Table!A:A,Metallic_Radius_Table!B:B)) -> 1.27 | P413: Ni | Q413: =IF(P413="","",_xlfn.XLOOKUP(TRIM(P413),Metallic_Radius_Table!A:A,Metallic_Radius_Table!B:B)) -> 1.24 | R413: =IF(G413>=1, "Ferromagnetic / Ferrimagnetic", IF(G413>=0.05, "Paramagnetic / Weakly magnetic", "Antiferromagnetic / Diamagnetic")) -> Ferromagnetic / Ferrimagnetic | U413: =IF(G413>=1, "FM → PM (Curie-type)", IF(G413<0.05, "AFM → PM (Néel-type)", "No long-range magnetic transition")) -> FM → PM (Curie-type)
A414: mp-1045038 | B414: YCr3O6 | C414: Cr, Y | D414: -2.6606957 | E414: 0.11810456 | F414: 1.6874 | G414: 35.999349 | H414: P-3m1 | I414: =TRUE() -> TRUE | J414: =IF(AND(CODE(MID(B414,2,1))>=97,CODE(MID(B414,2,1))<=122),LEFT(B414,2),LEFT(B414,1)) -> Y | K414: =IF(J414="","",_xlfn.XLOOKUP(TRIM(J414),Metallic_Radius_Table!A:A,Metallic_Radius_Table!B:B)) -> 1.8 | L414: =IF(ISNUMBER(SEARCH("La",B414)),"La", IF(ISNUMBER(SEARCH("Nd",B414)),"Nd", IF(ISNUMBER(SEARCH("Eu",B414)),"Eu", IF(ISNUMBER(SEARCH("Gd",B414)),"Gd","")))) | M414: =IF(L414="","",_xlfn.XLOOKUP(TRIM(L414),Metallic_Radius_Table!A:A,Metallic_Radius_Table!B:B)) | N414: =TRIM(LEFT(C414,FIND(",",C414)-1)) -> Cr | O414: =IF(N414="","",_xlfn.XLOOKUP(TRIM(N414),Metallic_Radius_Table!A:A,Metallic_Radius_Table!B:B)) -> 1.28 | P414: =TRIM(MID(C414,FIND(",",C414)+1,5)) -> Y | Q414: =IF(P414="","",_xlfn.XLOOKUP(TRIM(P414),Metallic_Radius_Table!A:A,Metallic_Radius_Table!B:B)) -> 1.8 | R414: =IF(G414>=1, "Ferromagnetic / Ferrimagnetic", IF(G414>=0.05, "Paramagnetic / Weakly magnetic", "Antiferromagnetic / Diamagnetic")) -> Ferromagnetic / Ferrimagnetic | U414: =IF(G414>=1, "FM → PM (Curie-type)", IF(G414<0.05, "AFM → PM (Néel-type)", "No long-range magnetic transition")) -> FM → PM (Curie-type)
A415: mp-1105234 | B415: YCrTeO6 | C415: Cr, Y | D415: -2.5308669 | E415: 0 | F415: 2.6946 | G415: 5.9994493 | H415: P-31c | I415: =TRUE() -> TRUE | J415: =IF(AND(CODE(MID(B415,2,1))>=97,CODE(MID(B415,2,1))<=122),LEFT(B415,2),LEFT(B415,1)) -> Y | K415: =IF(J415="","",_xlfn.XLOOKUP(TRIM(J415),Metallic_Radius_Table!A:A,Metallic_Radius_Table!B:B)) -> 1.8 | L415: =IF(ISNUMBER(SEARCH("La",B415)),"La", IF(ISNUMBER(SEARCH("Nd",B415)),"Nd", IF(ISNUMBER(SEARCH("Eu",B415)),"Eu", IF(ISNUMBER(SEARCH("Gd",B415)),"Gd","")))) | M415: =IF(L415="","",_xlfn.XLOOKUP(TRIM(L415),Metallic_Radius_Table!A:A,Metallic_Radius_Table!B:B)) | N415: =TRIM(LEFT(C415,FIND(",",C415)-1)) -> Cr | O415: =IF(N415="","",_xlfn.XLOOKUP(TRIM(N415),Metallic_Radius_Table!A:A,Metallic_Radius_Table!B:B)) -> 1.28 | P415: =TRIM(MID(C415,FIND(",",C415)+1,5)) -> Y | Q415: =IF(P415="","",_xlfn.XLOOKUP(TRIM(P415),Metallic_Radius_Table!A:A,Metallic_Radius_Table!B:B)) -> 1.8 | R415: =IF(G415>=1, "Ferromagnetic / Ferrimagnetic", IF(G415>=0.05, "Paramagnetic / Weakly magnetic", "Antiferromagnetic / Diamagnetic")) -> Ferromagnetic / Ferrimagnetic | U415: =IF(G415>=1, "FM → PM (Curie-type)", IF(G415<0.05, "AFM → PM (Néel-type)", "No long-range magnetic transition")) -> FM → PM (Curie-type)
A416: mp-1215956 | B416: Yb2MnCoO6 | C416: Co, Mn | D416: -2.9107236 | E416: 0 | F416: 0 | G416: 7.9999996 | H416: P2_1/c | I416: =TRUE() -> TRUE | J416: =IF(AND(CODE(MID(B416,2,1))>=97,CODE(MID(B416,2,1))<=122),LEFT(B416,2),LEFT(B416,1)) -> Yb | K416: =IF(J416="","",_xlfn.XLOOKUP(TRIM(J416),Metallic_Radius_Table!A:A,Metallic_Radius_Table!B:B)) -> 1.74 | L416: =IF(ISNUMBER(SEARCH("La",B416)),"La", IF(ISNUMBER(SEARCH("Nd",B416)),"Nd", IF(ISNUMBER(SEARCH("Eu",B416)),"Eu", IF(ISNUMBER(SEARCH("Gd",B416)),"Gd","")))) | M416: =IF(L416="","",_xlfn.XLOOKUP(TRIM(L416),Metallic_Radius_Table!A:A,Metallic_Radius_Table!B:B)) | N416: =TRIM(LEFT(C416,FIND(",",C416)-1)) -> Co | O416: =IF(N416="","",_xlfn.XLOOKUP(TRIM(N416),Metallic_Radius_Table!A:A,Metallic_Radius_Table!B:B)) -> 1.25 | P416: =TRIM(MID(C416,FIND(",",C416)+1,5)) -> Mn | Q416: =IF(P416="","",_xlfn.XLOOKUP(TRIM(P416),Metallic_Radius_Table!A:A,Metallic_Radius_Table!B:B)) -> 1.27 | R416: =IF(G416>=1, "Ferromagnetic / Ferrimagnetic", IF(G416>=0.05, "Paramagnetic / Weakly magnetic", "Antiferromagnetic / Diamagnetic")) -> Ferromagnetic / Ferrimagnetic | U416: =IF(G416>=1, "FM → PM (Curie-type)", IF(G416<0.05, "AFM → PM (Néel-type)", "No long-range magnetic transition")) -> FM → PM (Curie-type)
A417: mp-1215802 | B417: YbTaTiO6 | C417: Ta, Ti | D417: -3.51277 | E417: 0 | F417: 0 | G417: 0 | H417: P2_1/c | I417: =TRUE() -> TRUE | J417: =IF(AND(CODE(MID(B417,2,1))>=97,CODE(MID(B417,2,1))<=122),LEFT(B417,2),LEFT(B417,1)) -> Yb | K417: =IF(J417="","",_xlfn.XLOOKUP(TRIM(J417),Metallic_Radius_Table!A:A,Metallic_Radius_Table!B:B)) -> 1.74 | L417: =IF(ISNUMBER(SEARCH("La",B417)),"La", IF(ISNUMBER(SEARCH("Nd",B417)),"Nd", IF(ISNUMBER(SEARCH("Eu",B417)),"Eu", IF(ISNUMBER(SEARCH("Gd",B417)),"Gd","")))) | M417: =IF(L417="","",_xlfn.XLOOKUP(TRIM(L417),Metallic_Radius_Table!A:A,Metallic_Radius_Table!B:B)) | N417: =TRIM(LEFT(C417,FIND(",",C417)-1)) -> Ta | O417: =IF(N417="","",_xlfn.XLOOKUP(TRIM(N417),Metallic_Radius_Table!A:A,Metallic_Radius_Table!B:B)) -> 1.46 | P417: =TRIM(MID(C417,FIND(",",C417)+1,5)) -> Ti | Q417: =IF(P417="","",_xlfn.XLOOKUP(TRIM(P417),Metallic_Radius_Table!A:A,Metallic_Radius_Table!B:B)) -> 1.47 | R417: =IF(G417>=1, "Ferromagnetic / Ferrimagnetic", IF(G417>=0.05, "Paramagnetic / Weakly magnetic", "Antiferromagnetic / Diamagnetic")) -> Antiferromagnetic / Diamagnetic | U417: =IF(G417>=1, "FM → PM (Curie-type)", IF(G417<0.05, "AFM → PM (Néel-type)", "No long-range magnetic transition")) -> AFM → PM (Néel-type)

Sheet nontrue double perovskite
A1: Material ID | B1: Formula | C1: B-site metals | D1: Formation Energy (eV/atom) | E1: Energy Above Hull (eV) | F1: Band Gap (eV) | G1: Total Magnetization (Î¼B) | H1: Space Group | I1: Keep? | J1: element1 | K1: metallic radius1 | L1: element2 | M1: metallic radius 2 | N1: element3 | O1: metallic radius 3 | P1: element4 | Q1: metallic radius4 | R1: Magnetic State (inferred) | U1: Magnetic Transition (FM–PM / AFM–PM)
A2: mp-2230028 | B2: Ba2La2MgMn(WO6)2 | C2: Mn, W | D2: -2.8755737 | E2: 0.13257776 | F2: 2.2646 | G2: 6.9992259 | H2: C2/m | I2: =TRUE() -> TRUE | J2: =IF(AND(CODE(MID(B2,2,1))>=97,CODE(MID(B2,2,1))<=122),LEFT(B2,2),LEFT(B2,1)) -> Ba | K2: =IF(J2="","",_xlfn.XLOOKUP(TRIM(J2),Metallic_Radius_Table!A:A,Metallic_Radius_Table!B:B)) -> 2.17 | L2: =IF(ISNUMBER(SEARCH("La",B2)),"La", IF(ISNUMBER(SEARCH("Nd",B2)),"Nd", IF(ISNUMBER(SEARCH("Eu",B2)),"Eu", IF(ISNUMBER(SEARCH("Gd",B2)),"Gd","")))) -> La | M2: =IF(L2="","",_xlfn.XLOOKUP(TRIM(L2),Metallic_Radius_Table!A:A,Metallic_Radius_Table!B:B)) -> 1.87 | N2: =TRIM(LEFT(C2,FIND(",",C2)-1)) -> Mn | O2: =IF(N2="","",_xlfn.XLOOKUP(TRIM(N2),Metallic_Radius_Table!A:A,Metallic_Radius_Table!B:B)) -> 1.27 | P2: =TRIM(MID(C2,FIND(",",C2)+1,5)) -> W | Q2: =IF(P2="","",_xlfn.XLOOKUP(TRIM(P2),Metallic_Radius_Table!A:A,Metallic_Radius_Table!B:B)) -> 1.41 | R2: =IF(G2>=1, "Ferromagnetic / Ferrimagnetic", IF(G2>=0.05, "Paramagnetic / Weakly magnetic", "Antiferromagnetic / Diamagnetic")) -> Ferromagnetic / Ferrimagnetic | U2: =IF(G2>=1, "FM → PM (Curie-type)", IF(G2<0.05, "AFM → PM (Néel-type)", "No long-range magnetic transition")) -> FM → PM (Curie-type)
A3: mp-560825 | B3: Ba2La2Mn(WO6)2 | C3: Mn, W | D3: -2.9368683 | E3: 0.073534983 | F3: 1.5055 | G3: 0 | H3: R-3m | I3: =TRUE() -> TRUE | J3: =IF(AND(CODE(MID(B3,2,1))>=97,CODE(MID(B3,2,1))<=122),LEFT(B3,2),LEFT(B3,1)) -> Ba | K3: =IF(J3="","",_xlfn.XLOOKUP(TRIM(J3),Metallic_Radius_Table!A:A,Metallic_Radius_Table!B:B)) -> 2.17 | L3: =IF(ISNUMBER(SEARCH("La",B3)),"La", IF(ISNUMBER(SEARCH("Nd",B3)),"Nd", IF(ISNUMBER(SEARCH("Eu",B3)),"Eu", IF(ISNUMBER(SEARCH("Gd",B3)),"Gd","")))) -> La | M3: =IF(L3="","",_xlfn.XLOOKUP(TRIM(L3),Metallic_Radius_Table!A:A,Metallic_Radius_Table!B:B)) -> 1.87 | N3: =TRIM(LEFT(C3,FIND(",",C3)-1)) -> Mn | O3: =IF(N3="","",_xlfn.XLOOKUP(TRIM(N3),Metallic_Radius_Table!A:A,Metallic_Radius_Table!B:B)) -> 1.27 | P3: =TRIM(MID(C3,FIND(",",C3)+1,5)) -> W | Q3: =IF(P3="","",_xlfn.XLOOKUP(TRIM(P3),Metallic_Radius_Table!A:A,Metallic_Radius_Table!B:B)) -> 1.41 | R3: =IF(G3>=1, "Ferromagnetic / Ferrimagnetic", IF(G3>=0.05, "Paramagnetic / Weakly magnetic", "Antiferromagnetic / Diamagnetic")) -> Antiferromagnetic / Diamagnetic | U3: =IF(G3>=1, "FM → PM (Curie-type)", IF(G3<0.05, "AFM → PM (Néel-type)", "No long-range magnetic transition")) -> AFM → PM (Néel-type)
A4: mp-1228484 | B4: Ba2La2Ni(WO6)2 | C4: Ni, W | D4: -2.8645881 | E4: 0.049330128 | F4: 3.3024 | G4: 1.9999981 | H4: R-3m | I4: =TRUE() -> TRUE | J4: =IF(AND(CODE(MID(B4,2,1))>=97,CODE(MID(B4,2,1))<=122),LEFT(B4,2),LEFT(B4,1)) -> Ba | K4: =IF(J4="","",_xlfn.XLOOKUP(TRIM(J4),Metallic_Radius_Table!A:A,Metallic_Radius_Table!B:B)) -> 2.17 | L4: =IF(ISNUMBER(SEARCH("La",B4)),"La", IF(ISNUMBER(SEARCH("Nd",B4)),"Nd", IF(ISNUMBER(SEARCH("Eu",B4)),"Eu", IF(ISNUMBER(SEARCH("Gd",B4)),"Gd","")))) -> La | M4: =IF(L4="","",_xlfn.XLOOKUP(TRIM(L4),Metallic_Radius_Table!A:A,Metallic_Radius_Table!B:B)) -> 1.87 | N4: =TRIM(LEFT(C4,FIND(",",C4)-1)) -> Ni | O4: =IF(N4="","",_xlfn.XLOOKUP(TRIM(N4),Metallic_Radius_Table!A:A,Metallic_Radius_Table!B:B)) -> 1.24 | P4: =TRIM(MID(C4,FIND(",",C4)+1,5)) -> W | Q4: =IF(P4="","",_xlfn.XLOOKUP(TRIM(P4),Metallic_Radius_Table!A:A,Metallic_Radius_Table!B:B)) -> 1.41 | R4: =IF(G4>=1, "Ferromagnetic / Ferrimagnetic", IF(G4>=0.05, "Paramagnetic / Weakly magnetic", "Antiferromagnetic / Diamagnetic")) -> Ferromagnetic / Ferrimagnetic | U4: =IF(G4>=1, "FM → PM (Curie-type)", IF(G4<0.05, "AFM → PM (Néel-type)", "No long-range magnetic transition")) -> FM → PM (Curie-type)
A5: mp-2230422 | B5: Ba4MgCo(ReO6)2 | C5: Re, Co | D5: -2.5825823 | E5: 0.084036586 | F5: 0 | G5: 3.0158583 | H5: R-3m | I5: =TRUE() -> TRUE | J5: =IF(AND(CODE(MID(B5,2,1))>=97,CODE(MID(B5,2,1))<=122),LEFT(B5,2),LEFT(B5,1)) -> Ba | K5: =IF(J5="","",_xlfn.XLOOKUP(TRIM(J5),Metallic_Radius_Table!A:A,Metallic_Radius_Table!B:B)) -> 2.17 | L5: =IF(ISNUMBER(SEARCH("La",B5)),"La", IF(ISNUMBER(SEARCH("Nd",B5)),"Nd", IF(ISNUMBER(SEARCH("Eu",B5)),"Eu", IF(ISNUMBER(SEARCH("Gd",B5)),"Gd","")))) | M5: =IF(L5="","",_xlfn.XLOOKUP(TRIM(L5),Metallic_Radius_Table!A:A,Metallic_Radius_Table!B:B)) | N5: =TRIM(LEFT(C5,FIND(",",C5)-1)) -> Re | O5: =IF(N5="","",_xlfn.XLOOKUP(TRIM(N5),Metallic_Radius_Table!A:A,Metallic_Radius_Table!B:B)) -> 1.37 | P5: =TRIM(MID(C5,FIND(",",C5)+1,5)) -> Co | Q5: =IF(P5="","",_xlfn.XLOOKUP(TRIM(P5),Metallic_Radius_Table!A:A,Metallic_Radius_Table!B:B)) -> 1.25 | R5: =IF(G5>=1, "Ferromagnetic / Ferrimagnetic", IF(G5>=0.05, "Paramagnetic / Weakly magnetic", "Antiferromagnetic / Diamagnetic")) -> Ferromagnetic / Ferrimagnetic | U5: =IF(G5>=1, "FM → PM (Curie-type)", IF(G5<0.05, "AFM → PM (Néel-type)", "No long-range magnetic transition")) -> FM → PM (Curie-type)
A6: mp-1228145 | B6: Ba6Ca2Ta(RuO6)3 | C6: Ta, Ru | D6: -2.7240746 | E6: 0 | F6: 0 | G6: 3 | H6: P3m1 | I6: =TRUE() -> TRUE | J6: =IF(AND(CODE(MID(B6,2,1))>=97,CODE(MID(B6,2,1))<=122),LEFT(B6,2),LEFT(B6,1)) -> Ba | K6: =IF(J6="","",_xlfn.XLOOKUP(TRIM(J6),Metallic_Radius_Table!A:A,Metallic_Radius_Table!B:B)) -> 2.17 | L6: =IF(ISNUMBER(SEARCH("La",B6)),"La", IF(ISNUMBER(SEARCH("Nd",B6)),"Nd", IF(ISNUMBER(SEARCH("Eu",B6)),"Eu", IF(ISNUMBER(SEARCH("Gd",B6)),"Gd","")))) | M6: =IF(L6="","",_xlfn.XLOOKUP(TRIM(L6),Metallic_Radius_Table!A:A,Metallic_Radius_Table!B:B)) | N6: =TRIM(LEFT(C6,FIND(",",C6)-1)) -> Ta | O6: =IF(N6="","",_xlfn.XLOOKUP(TRIM(N6),Metallic_Radius_Table!A:A,Metallic_Radius_Table!B:B)) -> 1.46 | P6: =TRIM(MID(C6,FIND(",",C6)+1,5)) -> Ru | Q6: =IF(P6="","",_xlfn.XLOOKUP(TRIM(P6),Metallic_Radius_Table!A:A,Metallic_Radius_Table!B:B)) -> 1.34 | R6: =IF(G6>=1, "Ferromagnetic / Ferrimagnetic", IF(G6>=0.05, "Paramagnetic / Weakly magnetic", "Antiferromagnetic / Diamagnetic")) -> Ferromagnetic / Ferrimagnetic | U6: =IF(G6>=1, "FM → PM (Curie-type)", IF(G6<0.05, "AFM → PM (Néel-type)", "No long-range magnetic transition")) -> FM → PM (Curie-type)
A7: mp-684803 | B7: Ba3La3Mn2(WO6)3 | C7: Mn, W | D7: -2.8566314 | E7: 0.11743612 | F7: 1.495 | G7: 11.002872 | H7: R3m | I7: =TRUE() -> TRUE | J7: =IF(AND(CODE(MID(B7,2,1))>=97,CODE(MID(B7,2,1))<=122),LEFT(B7,2),LEFT(B7,1)) -> Ba | K7: =IF(J7="","",_xlfn.XLOOKUP(TRIM(J7),Metallic_Radius_Table!A:A,Metallic_Radius_Table!B:B)) -> 2.17 | L7: =IF(ISNUMBER(SEARCH("La",B7)),"La", IF(ISNUMBER(SEARCH("Nd",B7)),"Nd", IF(ISNUMBER(SEARCH("Eu",B7)),"Eu", IF(ISNUMBER(SEARCH("Gd",B7)),"Gd","")))) -> La | M7: =IF(L7="","",_xlfn.XLOOKUP(TRIM(L7),Metallic_Radius_Table!A:A,Metallic_Radius_Table!B:B)) -> 1.87 | N7: =TRIM(LEFT(C7,FIND(",",C7)-1)) -> Mn | O7: =IF(N7="","",_xlfn.XLOOKUP(TRIM(N7),Metallic_Radius_Table!A:A,Metallic_Radius_Table!B:B)) -> 1.27 | P7: =TRIM(MID(C7,FIND(",",C7)+1,5)) -> W | Q7: =IF(P7="","",_xlfn.XLOOKUP(TRIM(P7),Metallic_Radius_Table!A:A,Metallic_Radius_Table!B:B)) -> 1.41 | R7: =IF(G7>=1, "Ferromagnetic / Ferrimagnetic", IF(G7>=0.05, "Paramagnetic / Weakly magnetic", "Antiferromagnetic / Diamagnetic")) -> Ferromagnetic / Ferrimagnetic | U7: =IF(G7>=1, "FM → PM (Curie-type)", IF(G7<0.05, "AFM → PM (Néel-type)", "No long-range magnetic transition")) -> FM → PM (Curie-type)
A8: mp-1106249 | B8: Ba4Co(ReO6)2 | C8: Re, Co | D8: -2.6279541 | E8: 0 | F8: 1.536 | G8: 2.9999999 | H8: R-3m | I8: =TRUE() -> TRUE | J8: =IF(AND(CODE(MID(B8,2,1))>=97,CODE(MID(B8,2,1))<=122),LEFT(B8,2),LEFT(B8,1)) -> Ba | K8: =IF(J8="","",_xlfn.XLOOKUP(TRIM(J8),Metallic_Radius_Table!A:A,Metallic_Radius_Table!B:B)) -> 2.17 | L8: =IF(ISNUMBER(SEARCH("La",B8)),"La", IF(ISNUMBER(SEARCH("Nd",B8)),"Nd", IF(ISNUMBER(SEARCH("Eu",B8)),"Eu", IF(ISNUMBER(SEARCH("Gd",B8)),"Gd","")))) | M8: =IF(L8="","",_xlfn.XLOOKUP(TRIM(L8),Metallic_Radius_Table!A:A,Metallic_Radius_Table!B:B)) | N8: =TRIM(LEFT(C8,FIND(",",C8)-1)) -> Re | O8: =IF(N8="","",_xlfn.XLOOKUP(TRIM(N8),Metallic_Radius_Table!A:A,Metallic_Radius_Table!B:B)) -> 1.37 | P8: =TRIM(MID(C8,FIND(",",C8)+1,5)) -> Co | Q8: =IF(P8="","",_xlfn.XLOOKUP(TRIM(P8),Metallic_Radius_Table!A:A,Metallic_Radius_Table!B:B)) -> 1.25 | R8: =IF(G8>=1, "Ferromagnetic / Ferrimagnetic", IF(G8>=0.05, "Paramagnetic / Weakly magnetic", "Antiferromagnetic / Diamagnetic")) -> Ferromagnetic / Ferrimagnetic | U8: =IF(G8>=1, "FM → PM (Curie-type)", IF(G8<0.05, "AFM → PM (Néel-type)", "No long-range magnetic transition")) -> FM → PM (Curie-type)
A9: mp-1375060 | B9: CaLa2Mn2(FeO6)2 | C9: Fe, Mn | D9: -2.3782587 | E9: 0.16384981 | F9: 0 | G9: 13.998693 | H9: P1 | I9: =TRUE() -> TRUE | J9: =IF(AND(CODE(MID(B9,2,1))>=97,CODE(MID(B9,2,1))<=122),LEFT(B9,2),LEFT(B9,1)) -> Ca | K9: =IF(J9="","",_xlfn.XLOOKUP(TRIM(J9),Metallic_Radius_Table!A:A,Metallic_Radius_Table!B:B)) -> 1.97 | L9: =IF(ISNUMBER(SEARCH("La",B9)),"La", IF(ISNUMBER(SEARCH("Nd",B9)),"Nd", IF(ISNUMBER(SEARCH("Eu",B9)),"Eu", IF(ISNUMBER(SEARCH("Gd",B9)),"Gd","")))) -> La | M9: =IF(L9="","",_xlfn.XLOOKUP(TRIM(L9),Metallic_Radius_Table!A:A,Metallic_Radius_Table!B:B)) -> 1.87 | N9: =TRIM(LEFT(C9,FIND(",",C9)-1)) -> Fe | O9: =IF(N9="","",_xlfn.XLOOKUP(TRIM(N9),Metallic_Radius_Table!A:A,Metallic_Radius_Table!B:B)) -> 1.26 | P9: =TRIM(MID(C9,FIND(",",C9)+1,5)) -> Mn | Q9: =IF(P9="","",_xlfn.XLOOKUP(TRIM(P9),Metallic_Radius_Table!A:A,Metallic_Radius_Table!B:B)) -> 1.27 | R9: =IF(G9>=1, "Ferromagnetic / Ferrimagnetic", IF(G9>=0.05, "Paramagnetic / Weakly magnetic", "Antiferromagnetic / Diamagnetic")) -> Ferromagnetic / Ferrimagnetic | U9: =IF(G9>=1, "FM → PM (Curie-type)", IF(G9<0.05, "AFM → PM (Néel-type)", "No long-range magnetic transition")) -> FM → PM (Curie-type)
A10: mp-1233435 | B10: CaMn4(CoO6)2 | C10: Co, Mn | D10: -1.7730128 | E10: 0.097461768 | F10: 1.1607 | G10: 19.999465 | H10: C2 | I10: =TRUE() -> TRUE | J10: =IF(AND(CODE(MID(B10,2,1))>=97,CODE(MID(B10,2,1))<=122),LEFT(B10,2),LEFT(B10,1)) -> Ca | K10: =IF(J10="","",_xlfn.XLOOKUP(TRIM(J10),Metallic_Radius_Table!A:A,Metallic_Radius_Table!B:B)) -> 1.97 | L10: =IF(ISNUMBER(SEARCH("La",B10)),"La", IF(ISNUMBER(SEARCH("Nd",B10)),"Nd", IF(ISNUMBER(SEARCH("Eu",B10)),"Eu", IF(ISNUMBER(SEARCH("Gd",B10)),"Gd","")))) | M10: =IF(L10="","",_xlfn.XLOOKUP(TRIM(L10),Metallic_Radius_Table!A:A,Metallic_Radius_Table!B:B)) | N10: =TRIM(LEFT(C10,FIND(",",C10)-1)) -> Co | O10: =IF(N10="","",_xlfn.XLOOKUP(TRIM(N10),Metallic_Radius_Table!A:A,Metallic_Radius_Table!B:B)) -> 1.25 | P10: =TRIM(MID(C10,FIND(",",C10)+1,5)) -> Mn | Q10: =IF(P10="","",_xlfn.XLOOKUP(TRIM(P10),Metallic_Radius_Table!A:A,Metallic_Radius_Table!B:B)) -> 1.27 | R10: =IF(G10>=1, "Ferromagnetic / Ferrimagnetic", IF(G10>=0.05, "Paramagnetic / Weakly magnetic", "Antiferromagnetic / Diamagnetic")) -> Ferromagnetic / Ferrimagnetic | U10: =IF(G10>=1, "FM → PM (Curie-type)", IF(G10<0.05, "AFM → PM (Néel-type)", "No long-range magnetic transition")) -> FM → PM (Curie-type)
A11: mp-1234878 | B11: CaMn4(CoO6)2 | C11: Co, Mn | D11: -1.7700036 | E11: 0.10047101 | F11: 0.4937 | G11: 18.006983 | H11: P1 | I11: =TRUE() -> TRUE | J11: =IF(AND(CODE(MID(B11,2,1))>=97,CODE(MID(B11,2,1))<=122),LEFT(B11,2),LEFT(B11,1)) -> Ca | K11: =IF(J11="","",_xlfn.XLOOKUP(TRIM(J11),Metallic_Radius_Table!A:A,Metallic_Radius_Table!B:B)) -> 1.97 | L11: =IF(ISNUMBER(SEARCH("La",B11)),"La", IF(ISNUMBER(SEARCH("Nd",B11)),"Nd", IF(ISNUMBER(SEARCH("Eu",B11)),"Eu", IF(ISNUMBER(SEARCH("Gd",B11)),"Gd","")))) | M11: =IF(L11="","",_xlfn.XLOOKUP(TRIM(L11),Metallic_Radius_Table!A:A,Metallic_Radius_Table!B:B)) | N11: =TRIM(LEFT(C11,FIND(",",C11)-1)) -> Co | O11: =IF(N11="","",_xlfn.XLOOKUP(TRIM(N11),Metallic_Radius_Table!A:A,Metallic_Radius_Table!B:B)) -> 1.25 | P11: =TRIM(MID(C11,FIND(",",C11)+1,5)) -> Mn | Q11: =IF(P11="","",_xlfn.XLOOKUP(TRIM(P11),Metallic_Radius_Table!A:A,Metallic_Radius_Table!B:B)) -> 1.27 | R11: =IF(G11>=1, "Ferromagnetic / Ferrimagnetic", IF(G11>=0.05, "Paramagnetic / Weakly magnetic", "Antiferromagnetic / Diamagnetic")) -> Ferromagnetic / Ferrimagnetic | U11: =IF(G11>=1, "FM → PM (Curie-type)", IF(G11<0.05, "AFM → PM (Néel-type)", "No long-range magnetic transition")) -> FM → PM (Curie-type)
A12: mp-1233707 | B12: CaV4(NiO6)2 | C12: Ni, V | D12: -2.2372323 | E12: 0.10561043 | F12: 0 | G12: 6 | H12: C2 | I12: =TRUE() -> TRUE | J12: =IF(AND(CODE(MID(B12,2,1))>=97,CODE(MID(B12,2,1))<=122),LEFT(B12,2),LEFT(B12,1)) -> Ca | K12: =IF(J12="","",_xlfn.XLOOKUP(TRIM(J12),Metallic_Radius_Table!A:A,Metallic_Radius_Table!B:B)) -> 1.97 | L12: =IF(ISNUMBER(SEARCH("La",B12)),"La", IF(ISNUMBER(SEARCH("Nd",B12)),"Nd", IF(ISNUMBER(SEARCH("Eu",B12)),"Eu", IF(ISNUMBER(SEARCH("Gd",B12)),"Gd","")))) | M12: =IF(L12="","",_xlfn.XLOOKUP(TRIM(L12),Metallic_Radius_Table!A:A,Metallic_Radius_Table!B:B)) | N12: =TRIM(LEFT(C12,FIND(",",C12)-1)) -> Ni | O12: =IF(N12="","",_xlfn.XLOOKUP(TRIM(N12),Metallic_Radius_Table!A:A,Metallic_Radius_Table!B:B)) -> 1.24 | P12: =TRIM(MID(C12,FIND(",",C12)+1,5)) -> V | Q12: =IF(P12="","",_xlfn.XLOOKUP(TRIM(P12),Metallic_Radius_Table!A:A,Metallic_Radius_Table!B:B)) -> 1.34 | R12: =IF(G12>=1, "Ferromagnetic / Ferrimagnetic", IF(G12>=0.05, "Paramagnetic / Weakly magnetic", "Antiferromagnetic / Diamagnetic")) -> Ferromagnetic / Ferrimagnetic | U12: =IF(G12>=1, "FM → PM (Curie-type)", IF(G12<0.05, "AFM → PM (Néel-type)", "No long-range magnetic transition")) -> FM → PM (Curie-type)
A13: mp-1233711 | B13: CaV4(NiO6)2 | C13: Ni, V | D13: -2.158765 | E13: 0.18407778 | F13: 0.9981 | G13: 0.6355704 | H13: P1 | I13: =TRUE() -> TRUE | J13: =IF(AND(CODE(MID(B13,2,1))>=97,CODE(MID(B13,2,1))<=122),LEFT(B13,2),LEFT(B13,1)) -> Ca | K13: =IF(J13="","",_xlfn.XLOOKUP(TRIM(J13),Metallic_Radius_Table!A:A,Metallic_Radius_Table!B:B)) -> 1.97 | L13: =IF(ISNUMBER(SEARCH("La",B13)),"La", IF(ISNUMBER(SEARCH("Nd",B13)),"Nd", IF(ISNUMBER(SEARCH("Eu",B13)),"Eu", IF(ISNUMBER(SEARCH("Gd",B13)),"Gd","")))) | M13: =IF(L13="","",_xlfn.XLOOKUP(TRIM(L13),Metallic_Radius_Table!A:A,Metallic_Radius_Table!B:B)) | N13: =TRIM(LEFT(C13,FIND(",",C13)-1)) -> Ni | O13: =IF(N13="","",_xlfn.XLOOKUP(TRIM(N13),Metallic_Radius_Table!A:A,Metallic_Radius_Table!B:B)) -> 1.24 | P13: =TRIM(MID(C13,FIND(",",C13)+1,5)) -> V | Q13: =IF(P13="","",_xlfn.XLOOKUP(TRIM(P13),Metallic_Radius_Table!A:A,Metallic_Radius_Table!B:B)) -> 1.34 | R13: =IF(G13>=1, "Ferromagnetic / Ferrimagnetic", IF(G13>=0.05, "Paramagnetic / Weakly magnetic", "Antiferromagnetic / Diamagnetic")) -> Paramagnetic / Weakly magnetic | U13: =IF(G13>=1, "FM → PM (Curie-type)", IF(G13<0.05, "AFM → PM (Néel-type)", "No long-range magnetic transition")) -> No long-range magnetic transition
... A50: mp-1219593 | B50: RbNdTiNbO6F | C50: Nb, Ti | D50: -3.3644552 | E50: 0.043562876 | F50: 1.8523 | G50: 0.0011275 | H50: P4mm | I50: =TRUE() -> TRUE | J50: =IF(AND(CODE(MID(B50,2,1))>=97,CODE(MID(B50,2,1))<=122),LEFT(B50,2),LEFT(B50,1)) -> Rb | K50: =IF(J50="","",_xlfn.XLOOKUP(TRIM(J50),Metallic_Radius_Table!A:A,Metallic_Radius_Table!B:B)) -> 2.48 | L50: =IF(ISNUMBER(SEARCH("La",B50)),"La", IF(ISNUMBER(SEARCH("Nd",B50)),"Nd", IF(ISNUMBER(SEARCH("Eu",B50)),"Eu", IF(ISNUMBER(SEARCH("Gd",B50)),"Gd","")))) -> Nd | M50: =IF(L50="","",_xlfn.XLOOKUP(TRIM(L50),Metallic_Radius_Table!A:A,Metallic_Radius_Table!B:B)) -> 1.82 | N50: =TRIM(LEFT(C50,FIND(",",C50)-1)) -> Nb | O50: =IF(N50="","",_xlfn.XLOOKUP(TRIM(N50),Metallic_Radius_Table!A:A,Metallic_Radius_Table!B:B)) -> 1.46 | P50: =TRIM(MID(C50,FIND(",",C50)+1,5)) -> Ti | Q50: =IF(P50="","",_xlfn.XLOOKUP(TRIM(P50),Metallic_Radius_Table!A:A,Metallic_Radius_Table!B:B)) -> 1.47 | R50: =IF(G50>=1, "Ferromagnetic / Ferrimagnetic", IF(G50>=0.05, "Paramagnetic / Weakly magnetic", "Antiferromagnetic / Diamagnetic")) -> Antiferromagnetic / Diamagnetic | U50: =IF(G50>=1, "FM → PM (Curie-type)", IF(G50<0.05, "AFM → PM (Néel-type)", "No long-range magnetic transition")) -> AFM → PM (Néel-type)
A51: mp-1324685 | B51: Y5Mn3(NiO6)3 | C51: Mn, Ni, Y | D51: -2.4930836 | E51: 0.082007301 | F51: 0 | G51: 24.000001 | H51: Pc | I51: =TRUE() -> TRUE | J51: =IF(AND(CODE(MID(B51,2,1))>=97,CODE(MID(B51,2,1))<=122),LEFT(B51,2),LEFT(B51,1)) -> Y | K51: =IF(J51="","",_xlfn.XLOOKUP(TRIM(J51),Metallic_Radius_Table!A:A,Metallic_Radius_Table!B:B)) -> 1.8 | L51: =IF(ISNUMBER(SEARCH("La",B51)),"La", IF(ISNUMBER(SEARCH("Nd",B51)),"Nd", IF(ISNUMBER(SEARCH("Eu",B51)),"Eu", IF(ISNUMBER(SEARCH("Gd",B51)),"Gd","")))) | M51: =IF(L51="","",_xlfn.XLOOKUP(TRIM(L51),Metallic_Radius_Table!A:A,Metallic_Radius_Table!B:B)) | N51: =TRIM(LEFT(C51,FIND(",",C51)-1)) -> Mn | O51: =IF(N51="","",_xlfn.XLOOKUP(TRIM(N51),Metallic_Radius_Table!A:A,Metallic_Radius_Table!B:B)) -> 1.27 | P51: Ni | Q51: =IF(P51="","",_xlfn.XLOOKUP(TRIM(P51),Metallic_Radius_Table!A:A,Metallic_Radius_Table!B:B)) -> 1.24 | R51: =IF(G51>=1, "Ferromagnetic / Ferrimagnetic", IF(G51>=0.05, "Paramagnetic / Weakly magnetic", "Antiferromagnetic / Diamagnetic")) -> Ferromagnetic / Ferrimagnetic | U51: =IF(G51>=1, "FM → PM (Curie-type)", IF(G51<0.05, "AFM → PM (Néel-type)", "No long-range magnetic transition")) -> FM → PM (Curie-type)
A52: mp-686765 | B52: YTi2CdO6F | C52: Cd, Ti, Y | D52: -3.177678 | E52: 0.14274119 | F52: 1.3491 | G52: 5.2e-05 | H52: Imma | I52: =TRUE() -> TRUE | J52: =IF(AND(CODE(MID(B52,2,1))>=97,CODE(MID(B52,2,1))<=122),LEFT(B52,2),LEFT(B52,1)) -> Y | K52: =IF(J52="","",_xlfn.XLOOKUP(TRIM(J52),Metallic_Radius_Table!A:A,Metallic_Radius_Table!B:B)) -> 1.8 | L52: =IF(ISNUMBER(SEARCH("La",B52)),"La", IF(ISNUMBER(SEARCH("Nd",B52)),"Nd", IF(ISNUMBER(SEARCH("Eu",B52)),"Eu", IF(ISNUMBER(SEARCH("Gd",B52)),"Gd","")))) | M52: =IF(L52="","",_xlfn.XLOOKUP(TRIM(L52),Metallic_Radius_Table!A:A,Metallic_Radius_Table!B:B)) | N52: =TRIM(LEFT(C52,FIND(",",C52)-1)) -> Cd | O52: =IF(N52="","",_xlfn.XLOOKUP(TRIM(N52),Metallic_Radius_Table!A:A,Metallic_Radius_Table!B:B)) -> 1.58 | P52: Ti | Q52: =IF(P52="","",_xlfn.XLOOKUP(TRIM(P52),Metallic_Radius_Table!A:A,Metallic_Radius_Table!B:B)) -> 1.47 | R52: =IF(G52>=1, "Ferromagnetic / Ferrimagnetic", IF(G52>=0.05, "Paramagnetic / Weakly magnetic", "Antiferromagnetic / Diamagnetic")) -> Antiferromagnetic / Diamagnetic | U52: =IF(G52>=1, "FM → PM (Curie-type)", IF(G52<0.05, "AFM → PM (Néel-type)", "No long-range magnetic transition")) -> AFM → PM (Néel-type)
